[2024-02-01T12:57:08.449+0000] {processor.py:161} INFO - Started process (PID=55) to work on /opt/airflow/dags/s3_postgres_dag.py
[2024-02-01T12:57:08.471+0000] {processor.py:830} INFO - Processing file /opt/airflow/dags/s3_postgres_dag.py for tasks to queue
[2024-02-01T12:57:08.504+0000] {logging_mixin.py:188} INFO - [2024-02-01T12:57:08.485+0000] {dagbag.py:538} INFO - Filling up the DagBag from /opt/airflow/dags/s3_postgres_dag.py
[2024-02-01T12:57:09.063+0000] {processor.py:840} INFO - DAG(s) 'your_dag_name' retrieved from /opt/airflow/dags/s3_postgres_dag.py
[2024-02-01T12:57:10.284+0000] {logging_mixin.py:188} INFO - [2024-02-01T12:57:10.282+0000] {override.py:1769} INFO - Created Permission View: can edit on DAG:your_dag_name
[2024-02-01T12:57:10.359+0000] {logging_mixin.py:188} INFO - [2024-02-01T12:57:10.358+0000] {override.py:1769} INFO - Created Permission View: can read on DAG:your_dag_name
[2024-02-01T12:57:10.440+0000] {logging_mixin.py:188} INFO - [2024-02-01T12:57:10.439+0000] {override.py:1769} INFO - Created Permission View: can delete on DAG:your_dag_name
[2024-02-01T12:57:10.444+0000] {logging_mixin.py:188} INFO - [2024-02-01T12:57:10.443+0000] {dag.py:3036} INFO - Sync 1 DAGs
[2024-02-01T12:57:10.542+0000] {logging_mixin.py:188} INFO - [2024-02-01T12:57:10.542+0000] {dag.py:3058} INFO - Creating ORM DAG for your_dag_name
[2024-02-01T12:57:10.650+0000] {logging_mixin.py:188} INFO - [2024-02-01T12:57:10.648+0000] {dag.py:3823} INFO - Setting next_dagrun for your_dag_name to 2024-01-31 00:00:00+00:00, run_after=2024-02-01 00:00:00+00:00
[2024-02-01T12:57:10.784+0000] {processor.py:183} INFO - Processing /opt/airflow/dags/s3_postgres_dag.py took 2.484 seconds
[2024-02-01T12:57:41.408+0000] {processor.py:161} INFO - Started process (PID=56) to work on /opt/airflow/dags/s3_postgres_dag.py
[2024-02-01T12:57:41.412+0000] {processor.py:830} INFO - Processing file /opt/airflow/dags/s3_postgres_dag.py for tasks to queue
[2024-02-01T12:57:41.414+0000] {logging_mixin.py:188} INFO - [2024-02-01T12:57:41.414+0000] {dagbag.py:538} INFO - Filling up the DagBag from /opt/airflow/dags/s3_postgres_dag.py
[2024-02-01T12:57:41.449+0000] {processor.py:840} INFO - DAG(s) 'your_dag_name' retrieved from /opt/airflow/dags/s3_postgres_dag.py
[2024-02-01T12:57:41.498+0000] {logging_mixin.py:188} INFO - [2024-02-01T12:57:41.498+0000] {dag.py:3036} INFO - Sync 1 DAGs
[2024-02-01T12:57:41.567+0000] {logging_mixin.py:188} INFO - [2024-02-01T12:57:41.566+0000] {dag.py:3823} INFO - Setting next_dagrun for your_dag_name to 2024-01-31 00:00:00+00:00, run_after=2024-02-01 00:00:00+00:00
[2024-02-01T12:57:41.663+0000] {processor.py:183} INFO - Processing /opt/airflow/dags/s3_postgres_dag.py took 0.262 seconds
[2024-02-01T12:58:12.069+0000] {processor.py:161} INFO - Started process (PID=57) to work on /opt/airflow/dags/s3_postgres_dag.py
[2024-02-01T12:58:12.071+0000] {processor.py:830} INFO - Processing file /opt/airflow/dags/s3_postgres_dag.py for tasks to queue
[2024-02-01T12:58:12.073+0000] {logging_mixin.py:188} INFO - [2024-02-01T12:58:12.073+0000] {dagbag.py:538} INFO - Filling up the DagBag from /opt/airflow/dags/s3_postgres_dag.py
[2024-02-01T12:58:12.114+0000] {processor.py:840} INFO - DAG(s) 'your_dag_name' retrieved from /opt/airflow/dags/s3_postgres_dag.py
[2024-02-01T12:58:12.163+0000] {logging_mixin.py:188} INFO - [2024-02-01T12:58:12.162+0000] {dag.py:3036} INFO - Sync 1 DAGs
[2024-02-01T12:58:12.201+0000] {logging_mixin.py:188} INFO - [2024-02-01T12:58:12.201+0000] {dag.py:3823} INFO - Setting next_dagrun for your_dag_name to 2024-01-31 00:00:00+00:00, run_after=2024-02-01 00:00:00+00:00
[2024-02-01T12:58:12.298+0000] {processor.py:183} INFO - Processing /opt/airflow/dags/s3_postgres_dag.py took 0.232 seconds
[2024-02-01T12:58:25.732+0000] {processor.py:161} INFO - Started process (PID=58) to work on /opt/airflow/dags/s3_postgres_dag.py
[2024-02-01T12:58:25.734+0000] {processor.py:830} INFO - Processing file /opt/airflow/dags/s3_postgres_dag.py for tasks to queue
[2024-02-01T12:58:25.737+0000] {logging_mixin.py:188} INFO - [2024-02-01T12:58:25.736+0000] {dagbag.py:538} INFO - Filling up the DagBag from /opt/airflow/dags/s3_postgres_dag.py
[2024-02-01T12:58:25.788+0000] {logging_mixin.py:188} INFO - [2024-02-01T12:58:25.778+0000] {dagbag.py:348} ERROR - Failed to import: /opt/airflow/dags/s3_postgres_dag.py
Traceback (most recent call last):
  File "/home/airflow/.local/lib/python3.8/site-packages/airflow/models/dagbag.py", line 344, in parse
    loader.exec_module(new_module)
  File "<frozen importlib._bootstrap_external>", line 843, in exec_module
  File "<frozen importlib._bootstrap>", line 219, in _call_with_frames_removed
  File "/opt/airflow/dags/s3_postgres_dag.py", line 2, in <module>
    from airflow import PythonOperator
ImportError: cannot import name 'PythonOperator' from 'airflow' (/home/airflow/.local/lib/python3.8/site-packages/airflow/__init__.py)
[2024-02-01T12:58:25.790+0000] {processor.py:842} WARNING - No viable dags retrieved from /opt/airflow/dags/s3_postgres_dag.py
[2024-02-01T12:58:25.844+0000] {processor.py:183} INFO - Processing /opt/airflow/dags/s3_postgres_dag.py took 0.116 seconds
[2024-02-01T12:58:56.442+0000] {processor.py:161} INFO - Started process (PID=59) to work on /opt/airflow/dags/s3_postgres_dag.py
[2024-02-01T12:58:56.445+0000] {processor.py:830} INFO - Processing file /opt/airflow/dags/s3_postgres_dag.py for tasks to queue
[2024-02-01T12:58:56.448+0000] {logging_mixin.py:188} INFO - [2024-02-01T12:58:56.447+0000] {dagbag.py:538} INFO - Filling up the DagBag from /opt/airflow/dags/s3_postgres_dag.py
[2024-02-01T12:58:56.475+0000] {logging_mixin.py:188} INFO - [2024-02-01T12:58:56.469+0000] {dagbag.py:348} ERROR - Failed to import: /opt/airflow/dags/s3_postgres_dag.py
Traceback (most recent call last):
  File "/home/airflow/.local/lib/python3.8/site-packages/airflow/models/dagbag.py", line 344, in parse
    loader.exec_module(new_module)
  File "<frozen importlib._bootstrap_external>", line 843, in exec_module
  File "<frozen importlib._bootstrap>", line 219, in _call_with_frames_removed
  File "/opt/airflow/dags/s3_postgres_dag.py", line 2, in <module>
    from airflow import PythonOperator
ImportError: cannot import name 'PythonOperator' from 'airflow' (/home/airflow/.local/lib/python3.8/site-packages/airflow/__init__.py)
[2024-02-01T12:58:56.477+0000] {processor.py:842} WARNING - No viable dags retrieved from /opt/airflow/dags/s3_postgres_dag.py
[2024-02-01T12:58:56.531+0000] {processor.py:183} INFO - Processing /opt/airflow/dags/s3_postgres_dag.py took 0.092 seconds
[2024-02-01T12:59:27.534+0000] {processor.py:161} INFO - Started process (PID=60) to work on /opt/airflow/dags/s3_postgres_dag.py
[2024-02-01T12:59:27.536+0000] {processor.py:830} INFO - Processing file /opt/airflow/dags/s3_postgres_dag.py for tasks to queue
[2024-02-01T12:59:27.537+0000] {logging_mixin.py:188} INFO - [2024-02-01T12:59:27.537+0000] {dagbag.py:538} INFO - Filling up the DagBag from /opt/airflow/dags/s3_postgres_dag.py
[2024-02-01T12:59:27.560+0000] {logging_mixin.py:188} INFO - [2024-02-01T12:59:27.555+0000] {dagbag.py:348} ERROR - Failed to import: /opt/airflow/dags/s3_postgres_dag.py
Traceback (most recent call last):
  File "/home/airflow/.local/lib/python3.8/site-packages/airflow/models/dagbag.py", line 344, in parse
    loader.exec_module(new_module)
  File "<frozen importlib._bootstrap_external>", line 843, in exec_module
  File "<frozen importlib._bootstrap>", line 219, in _call_with_frames_removed
  File "/opt/airflow/dags/s3_postgres_dag.py", line 2, in <module>
    from airflow import PythonOperator
ImportError: cannot import name 'PythonOperator' from 'airflow' (/home/airflow/.local/lib/python3.8/site-packages/airflow/__init__.py)
[2024-02-01T12:59:27.562+0000] {processor.py:842} WARNING - No viable dags retrieved from /opt/airflow/dags/s3_postgres_dag.py
[2024-02-01T12:59:27.628+0000] {processor.py:183} INFO - Processing /opt/airflow/dags/s3_postgres_dag.py took 0.097 seconds
[2024-02-01T12:59:37.982+0000] {processor.py:161} INFO - Started process (PID=61) to work on /opt/airflow/dags/s3_postgres_dag.py
[2024-02-01T12:59:37.984+0000] {processor.py:830} INFO - Processing file /opt/airflow/dags/s3_postgres_dag.py for tasks to queue
[2024-02-01T12:59:37.987+0000] {logging_mixin.py:188} INFO - [2024-02-01T12:59:37.986+0000] {dagbag.py:538} INFO - Filling up the DagBag from /opt/airflow/dags/s3_postgres_dag.py
[2024-02-01T12:59:38.081+0000] {logging_mixin.py:188} INFO - [2024-02-01T12:59:38.070+0000] {dagbag.py:348} ERROR - Failed to import: /opt/airflow/dags/s3_postgres_dag.py
Traceback (most recent call last):
  File "/home/airflow/.local/lib/python3.8/site-packages/airflow/models/dagbag.py", line 344, in parse
    loader.exec_module(new_module)
  File "<frozen importlib._bootstrap_external>", line 843, in exec_module
  File "<frozen importlib._bootstrap>", line 219, in _call_with_frames_removed
  File "/opt/airflow/dags/s3_postgres_dag.py", line 2, in <module>
    from airflow import PythonOperator
ImportError: cannot import name 'PythonOperator' from 'airflow' (/home/airflow/.local/lib/python3.8/site-packages/airflow/__init__.py)
[2024-02-01T12:59:38.089+0000] {processor.py:842} WARNING - No viable dags retrieved from /opt/airflow/dags/s3_postgres_dag.py
[2024-02-01T12:59:38.194+0000] {processor.py:183} INFO - Processing /opt/airflow/dags/s3_postgres_dag.py took 0.217 seconds
[2024-02-01T13:00:09.114+0000] {processor.py:161} INFO - Started process (PID=62) to work on /opt/airflow/dags/s3_postgres_dag.py
[2024-02-01T13:00:09.115+0000] {processor.py:830} INFO - Processing file /opt/airflow/dags/s3_postgres_dag.py for tasks to queue
[2024-02-01T13:00:09.117+0000] {logging_mixin.py:188} INFO - [2024-02-01T13:00:09.116+0000] {dagbag.py:538} INFO - Filling up the DagBag from /opt/airflow/dags/s3_postgres_dag.py
[2024-02-01T13:00:09.150+0000] {logging_mixin.py:188} INFO - [2024-02-01T13:00:09.142+0000] {dagbag.py:348} ERROR - Failed to import: /opt/airflow/dags/s3_postgres_dag.py
Traceback (most recent call last):
  File "/home/airflow/.local/lib/python3.8/site-packages/airflow/models/dagbag.py", line 344, in parse
    loader.exec_module(new_module)
  File "<frozen importlib._bootstrap_external>", line 843, in exec_module
  File "<frozen importlib._bootstrap>", line 219, in _call_with_frames_removed
  File "/opt/airflow/dags/s3_postgres_dag.py", line 2, in <module>
    from airflow import PythonOperator
ImportError: cannot import name 'PythonOperator' from 'airflow' (/home/airflow/.local/lib/python3.8/site-packages/airflow/__init__.py)
[2024-02-01T13:00:09.152+0000] {processor.py:842} WARNING - No viable dags retrieved from /opt/airflow/dags/s3_postgres_dag.py
[2024-02-01T13:00:09.202+0000] {processor.py:183} INFO - Processing /opt/airflow/dags/s3_postgres_dag.py took 0.091 seconds
[2024-02-01T13:00:40.075+0000] {processor.py:161} INFO - Started process (PID=63) to work on /opt/airflow/dags/s3_postgres_dag.py
[2024-02-01T13:00:40.079+0000] {processor.py:830} INFO - Processing file /opt/airflow/dags/s3_postgres_dag.py for tasks to queue
[2024-02-01T13:00:40.085+0000] {logging_mixin.py:188} INFO - [2024-02-01T13:00:40.085+0000] {dagbag.py:538} INFO - Filling up the DagBag from /opt/airflow/dags/s3_postgres_dag.py
[2024-02-01T13:00:40.139+0000] {logging_mixin.py:188} INFO - [2024-02-01T13:00:40.132+0000] {dagbag.py:348} ERROR - Failed to import: /opt/airflow/dags/s3_postgres_dag.py
Traceback (most recent call last):
  File "/home/airflow/.local/lib/python3.8/site-packages/airflow/models/dagbag.py", line 344, in parse
    loader.exec_module(new_module)
  File "<frozen importlib._bootstrap_external>", line 843, in exec_module
  File "<frozen importlib._bootstrap>", line 219, in _call_with_frames_removed
  File "/opt/airflow/dags/s3_postgres_dag.py", line 2, in <module>
    from airflow import PythonOperator
ImportError: cannot import name 'PythonOperator' from 'airflow' (/home/airflow/.local/lib/python3.8/site-packages/airflow/__init__.py)
[2024-02-01T13:00:40.143+0000] {processor.py:842} WARNING - No viable dags retrieved from /opt/airflow/dags/s3_postgres_dag.py
[2024-02-01T13:00:40.209+0000] {processor.py:183} INFO - Processing /opt/airflow/dags/s3_postgres_dag.py took 0.141 seconds
[2024-02-01T13:01:11.616+0000] {processor.py:161} INFO - Started process (PID=64) to work on /opt/airflow/dags/s3_postgres_dag.py
[2024-02-01T13:01:11.619+0000] {processor.py:830} INFO - Processing file /opt/airflow/dags/s3_postgres_dag.py for tasks to queue
[2024-02-01T13:01:11.632+0000] {logging_mixin.py:188} INFO - [2024-02-01T13:01:11.631+0000] {dagbag.py:538} INFO - Filling up the DagBag from /opt/airflow/dags/s3_postgres_dag.py
[2024-02-01T13:01:11.835+0000] {logging_mixin.py:188} INFO - [2024-02-01T13:01:11.786+0000] {dagbag.py:348} ERROR - Failed to import: /opt/airflow/dags/s3_postgres_dag.py
Traceback (most recent call last):
  File "/home/airflow/.local/lib/python3.8/site-packages/airflow/models/dagbag.py", line 344, in parse
    loader.exec_module(new_module)
  File "<frozen importlib._bootstrap_external>", line 843, in exec_module
  File "<frozen importlib._bootstrap>", line 219, in _call_with_frames_removed
  File "/opt/airflow/dags/s3_postgres_dag.py", line 2, in <module>
    from airflow import PythonOperator
ImportError: cannot import name 'PythonOperator' from 'airflow' (/home/airflow/.local/lib/python3.8/site-packages/airflow/__init__.py)
[2024-02-01T13:01:11.865+0000] {processor.py:842} WARNING - No viable dags retrieved from /opt/airflow/dags/s3_postgres_dag.py
[2024-02-01T13:01:12.098+0000] {processor.py:183} INFO - Processing /opt/airflow/dags/s3_postgres_dag.py took 0.498 seconds
[2024-02-01T13:01:43.148+0000] {processor.py:161} INFO - Started process (PID=65) to work on /opt/airflow/dags/s3_postgres_dag.py
[2024-02-01T13:01:43.151+0000] {processor.py:830} INFO - Processing file /opt/airflow/dags/s3_postgres_dag.py for tasks to queue
[2024-02-01T13:01:43.153+0000] {logging_mixin.py:188} INFO - [2024-02-01T13:01:43.152+0000] {dagbag.py:538} INFO - Filling up the DagBag from /opt/airflow/dags/s3_postgres_dag.py
[2024-02-01T13:01:43.198+0000] {logging_mixin.py:188} INFO - [2024-02-01T13:01:43.187+0000] {dagbag.py:348} ERROR - Failed to import: /opt/airflow/dags/s3_postgres_dag.py
Traceback (most recent call last):
  File "/home/airflow/.local/lib/python3.8/site-packages/airflow/models/dagbag.py", line 344, in parse
    loader.exec_module(new_module)
  File "<frozen importlib._bootstrap_external>", line 843, in exec_module
  File "<frozen importlib._bootstrap>", line 219, in _call_with_frames_removed
  File "/opt/airflow/dags/s3_postgres_dag.py", line 2, in <module>
    from airflow import PythonOperator
ImportError: cannot import name 'PythonOperator' from 'airflow' (/home/airflow/.local/lib/python3.8/site-packages/airflow/__init__.py)
[2024-02-01T13:01:43.201+0000] {processor.py:842} WARNING - No viable dags retrieved from /opt/airflow/dags/s3_postgres_dag.py
[2024-02-01T13:01:43.281+0000] {processor.py:183} INFO - Processing /opt/airflow/dags/s3_postgres_dag.py took 0.138 seconds
[2024-02-01T13:02:13.582+0000] {processor.py:161} INFO - Started process (PID=66) to work on /opt/airflow/dags/s3_postgres_dag.py
[2024-02-01T13:02:13.596+0000] {processor.py:830} INFO - Processing file /opt/airflow/dags/s3_postgres_dag.py for tasks to queue
[2024-02-01T13:02:13.612+0000] {logging_mixin.py:188} INFO - [2024-02-01T13:02:13.609+0000] {dagbag.py:538} INFO - Filling up the DagBag from /opt/airflow/dags/s3_postgres_dag.py
[2024-02-01T13:02:13.699+0000] {logging_mixin.py:188} INFO - [2024-02-01T13:02:13.686+0000] {dagbag.py:348} ERROR - Failed to import: /opt/airflow/dags/s3_postgres_dag.py
Traceback (most recent call last):
  File "/home/airflow/.local/lib/python3.8/site-packages/airflow/models/dagbag.py", line 344, in parse
    loader.exec_module(new_module)
  File "<frozen importlib._bootstrap_external>", line 843, in exec_module
  File "<frozen importlib._bootstrap>", line 219, in _call_with_frames_removed
  File "/opt/airflow/dags/s3_postgres_dag.py", line 2, in <module>
    from airflow import PythonOperator
ImportError: cannot import name 'PythonOperator' from 'airflow' (/home/airflow/.local/lib/python3.8/site-packages/airflow/__init__.py)
[2024-02-01T13:02:13.704+0000] {processor.py:842} WARNING - No viable dags retrieved from /opt/airflow/dags/s3_postgres_dag.py
[2024-02-01T13:02:13.936+0000] {processor.py:183} INFO - Processing /opt/airflow/dags/s3_postgres_dag.py took 0.395 seconds
[2024-02-01T13:02:43.924+0000] {processor.py:161} INFO - Started process (PID=67) to work on /opt/airflow/dags/s3_postgres_dag.py
[2024-02-01T13:02:43.928+0000] {processor.py:830} INFO - Processing file /opt/airflow/dags/s3_postgres_dag.py for tasks to queue
[2024-02-01T13:02:43.931+0000] {logging_mixin.py:188} INFO - [2024-02-01T13:02:43.930+0000] {dagbag.py:538} INFO - Filling up the DagBag from /opt/airflow/dags/s3_postgres_dag.py
[2024-02-01T13:02:44.016+0000] {logging_mixin.py:188} INFO - [2024-02-01T13:02:44.001+0000] {dagbag.py:348} ERROR - Failed to import: /opt/airflow/dags/s3_postgres_dag.py
Traceback (most recent call last):
  File "/home/airflow/.local/lib/python3.8/site-packages/airflow/models/dagbag.py", line 344, in parse
    loader.exec_module(new_module)
  File "<frozen importlib._bootstrap_external>", line 843, in exec_module
  File "<frozen importlib._bootstrap>", line 219, in _call_with_frames_removed
  File "/opt/airflow/dags/s3_postgres_dag.py", line 15, in <module>
    dag = DAG(
  File "/home/airflow/.local/lib/python3.8/site-packages/airflow/models/dag.py", line 557, in __init__
    raise ValueError("DAG is missing the start_date parameter")
ValueError: DAG is missing the start_date parameter
[2024-02-01T13:02:44.019+0000] {processor.py:842} WARNING - No viable dags retrieved from /opt/airflow/dags/s3_postgres_dag.py
[2024-02-01T13:02:44.089+0000] {processor.py:183} INFO - Processing /opt/airflow/dags/s3_postgres_dag.py took 0.169 seconds
[2024-02-01T13:03:14.989+0000] {processor.py:161} INFO - Started process (PID=68) to work on /opt/airflow/dags/s3_postgres_dag.py
[2024-02-01T13:03:14.991+0000] {processor.py:830} INFO - Processing file /opt/airflow/dags/s3_postgres_dag.py for tasks to queue
[2024-02-01T13:03:14.993+0000] {logging_mixin.py:188} INFO - [2024-02-01T13:03:14.992+0000] {dagbag.py:538} INFO - Filling up the DagBag from /opt/airflow/dags/s3_postgres_dag.py
[2024-02-01T13:03:15.038+0000] {logging_mixin.py:188} INFO - [2024-02-01T13:03:15.028+0000] {dagbag.py:348} ERROR - Failed to import: /opt/airflow/dags/s3_postgres_dag.py
Traceback (most recent call last):
  File "/home/airflow/.local/lib/python3.8/site-packages/airflow/models/dagbag.py", line 344, in parse
    loader.exec_module(new_module)
  File "<frozen importlib._bootstrap_external>", line 843, in exec_module
  File "<frozen importlib._bootstrap>", line 219, in _call_with_frames_removed
  File "/opt/airflow/dags/s3_postgres_dag.py", line 15, in <module>
    dag = DAG(
  File "/home/airflow/.local/lib/python3.8/site-packages/airflow/models/dag.py", line 557, in __init__
    raise ValueError("DAG is missing the start_date parameter")
ValueError: DAG is missing the start_date parameter
[2024-02-01T13:03:15.041+0000] {processor.py:842} WARNING - No viable dags retrieved from /opt/airflow/dags/s3_postgres_dag.py
[2024-02-01T13:03:15.138+0000] {processor.py:183} INFO - Processing /opt/airflow/dags/s3_postgres_dag.py took 0.153 seconds
[2024-02-01T13:03:45.977+0000] {processor.py:161} INFO - Started process (PID=69) to work on /opt/airflow/dags/s3_postgres_dag.py
[2024-02-01T13:03:45.978+0000] {processor.py:830} INFO - Processing file /opt/airflow/dags/s3_postgres_dag.py for tasks to queue
[2024-02-01T13:03:45.980+0000] {logging_mixin.py:188} INFO - [2024-02-01T13:03:45.979+0000] {dagbag.py:538} INFO - Filling up the DagBag from /opt/airflow/dags/s3_postgres_dag.py
[2024-02-01T13:03:46.002+0000] {logging_mixin.py:188} INFO - [2024-02-01T13:03:45.998+0000] {dagbag.py:348} ERROR - Failed to import: /opt/airflow/dags/s3_postgres_dag.py
Traceback (most recent call last):
  File "/home/airflow/.local/lib/python3.8/site-packages/airflow/models/dagbag.py", line 344, in parse
    loader.exec_module(new_module)
  File "<frozen importlib._bootstrap_external>", line 843, in exec_module
  File "<frozen importlib._bootstrap>", line 219, in _call_with_frames_removed
  File "/opt/airflow/dags/s3_postgres_dag.py", line 15, in <module>
    dag = DAG(
  File "/home/airflow/.local/lib/python3.8/site-packages/airflow/models/dag.py", line 557, in __init__
    raise ValueError("DAG is missing the start_date parameter")
ValueError: DAG is missing the start_date parameter
[2024-02-01T13:03:46.004+0000] {processor.py:842} WARNING - No viable dags retrieved from /opt/airflow/dags/s3_postgres_dag.py
[2024-02-01T13:03:46.044+0000] {processor.py:183} INFO - Processing /opt/airflow/dags/s3_postgres_dag.py took 0.071 seconds
[2024-02-01T13:04:16.760+0000] {processor.py:161} INFO - Started process (PID=70) to work on /opt/airflow/dags/s3_postgres_dag.py
[2024-02-01T13:04:16.761+0000] {processor.py:830} INFO - Processing file /opt/airflow/dags/s3_postgres_dag.py for tasks to queue
[2024-02-01T13:04:16.763+0000] {logging_mixin.py:188} INFO - [2024-02-01T13:04:16.762+0000] {dagbag.py:538} INFO - Filling up the DagBag from /opt/airflow/dags/s3_postgres_dag.py
[2024-02-01T13:04:16.791+0000] {logging_mixin.py:188} INFO - [2024-02-01T13:04:16.784+0000] {dagbag.py:348} ERROR - Failed to import: /opt/airflow/dags/s3_postgres_dag.py
Traceback (most recent call last):
  File "/home/airflow/.local/lib/python3.8/site-packages/airflow/models/dagbag.py", line 344, in parse
    loader.exec_module(new_module)
  File "<frozen importlib._bootstrap_external>", line 843, in exec_module
  File "<frozen importlib._bootstrap>", line 219, in _call_with_frames_removed
  File "/opt/airflow/dags/s3_postgres_dag.py", line 15, in <module>
    dag = DAG(
  File "/home/airflow/.local/lib/python3.8/site-packages/airflow/models/dag.py", line 557, in __init__
    raise ValueError("DAG is missing the start_date parameter")
ValueError: DAG is missing the start_date parameter
[2024-02-01T13:04:16.793+0000] {processor.py:842} WARNING - No viable dags retrieved from /opt/airflow/dags/s3_postgres_dag.py
[2024-02-01T13:04:16.849+0000] {processor.py:183} INFO - Processing /opt/airflow/dags/s3_postgres_dag.py took 0.093 seconds
[2024-02-01T13:04:47.840+0000] {processor.py:161} INFO - Started process (PID=71) to work on /opt/airflow/dags/s3_postgres_dag.py
[2024-02-01T13:04:47.842+0000] {processor.py:830} INFO - Processing file /opt/airflow/dags/s3_postgres_dag.py for tasks to queue
[2024-02-01T13:04:47.844+0000] {logging_mixin.py:188} INFO - [2024-02-01T13:04:47.843+0000] {dagbag.py:538} INFO - Filling up the DagBag from /opt/airflow/dags/s3_postgres_dag.py
[2024-02-01T13:04:47.877+0000] {logging_mixin.py:188} INFO - [2024-02-01T13:04:47.870+0000] {dagbag.py:348} ERROR - Failed to import: /opt/airflow/dags/s3_postgres_dag.py
Traceback (most recent call last):
  File "/home/airflow/.local/lib/python3.8/site-packages/airflow/models/dagbag.py", line 344, in parse
    loader.exec_module(new_module)
  File "<frozen importlib._bootstrap_external>", line 843, in exec_module
  File "<frozen importlib._bootstrap>", line 219, in _call_with_frames_removed
  File "/opt/airflow/dags/s3_postgres_dag.py", line 15, in <module>
    dag = DAG(
  File "/home/airflow/.local/lib/python3.8/site-packages/airflow/models/dag.py", line 557, in __init__
    raise ValueError("DAG is missing the start_date parameter")
ValueError: DAG is missing the start_date parameter
[2024-02-01T13:04:47.880+0000] {processor.py:842} WARNING - No viable dags retrieved from /opt/airflow/dags/s3_postgres_dag.py
[2024-02-01T13:04:47.928+0000] {processor.py:183} INFO - Processing /opt/airflow/dags/s3_postgres_dag.py took 0.091 seconds
[2024-02-01T13:05:18.980+0000] {processor.py:161} INFO - Started process (PID=72) to work on /opt/airflow/dags/s3_postgres_dag.py
[2024-02-01T13:05:18.982+0000] {processor.py:830} INFO - Processing file /opt/airflow/dags/s3_postgres_dag.py for tasks to queue
[2024-02-01T13:05:18.983+0000] {logging_mixin.py:188} INFO - [2024-02-01T13:05:18.983+0000] {dagbag.py:538} INFO - Filling up the DagBag from /opt/airflow/dags/s3_postgres_dag.py
[2024-02-01T13:05:19.020+0000] {logging_mixin.py:188} INFO - [2024-02-01T13:05:19.013+0000] {dagbag.py:348} ERROR - Failed to import: /opt/airflow/dags/s3_postgres_dag.py
Traceback (most recent call last):
  File "/home/airflow/.local/lib/python3.8/site-packages/airflow/models/dagbag.py", line 344, in parse
    loader.exec_module(new_module)
  File "<frozen importlib._bootstrap_external>", line 843, in exec_module
  File "<frozen importlib._bootstrap>", line 219, in _call_with_frames_removed
  File "/opt/airflow/dags/s3_postgres_dag.py", line 15, in <module>
    dag = DAG(
  File "/home/airflow/.local/lib/python3.8/site-packages/airflow/models/dag.py", line 557, in __init__
    raise ValueError("DAG is missing the start_date parameter")
ValueError: DAG is missing the start_date parameter
[2024-02-01T13:05:19.022+0000] {processor.py:842} WARNING - No viable dags retrieved from /opt/airflow/dags/s3_postgres_dag.py
[2024-02-01T13:05:19.066+0000] {processor.py:183} INFO - Processing /opt/airflow/dags/s3_postgres_dag.py took 0.093 seconds
[2024-02-01T13:05:49.817+0000] {processor.py:161} INFO - Started process (PID=73) to work on /opt/airflow/dags/s3_postgres_dag.py
[2024-02-01T13:05:49.818+0000] {processor.py:830} INFO - Processing file /opt/airflow/dags/s3_postgres_dag.py for tasks to queue
[2024-02-01T13:05:49.819+0000] {logging_mixin.py:188} INFO - [2024-02-01T13:05:49.819+0000] {dagbag.py:538} INFO - Filling up the DagBag from /opt/airflow/dags/s3_postgres_dag.py
[2024-02-01T13:05:49.850+0000] {logging_mixin.py:188} INFO - [2024-02-01T13:05:49.843+0000] {dagbag.py:348} ERROR - Failed to import: /opt/airflow/dags/s3_postgres_dag.py
Traceback (most recent call last):
  File "/home/airflow/.local/lib/python3.8/site-packages/airflow/models/dagbag.py", line 344, in parse
    loader.exec_module(new_module)
  File "<frozen importlib._bootstrap_external>", line 843, in exec_module
  File "<frozen importlib._bootstrap>", line 219, in _call_with_frames_removed
  File "/opt/airflow/dags/s3_postgres_dag.py", line 15, in <module>
    dag = DAG(
  File "/home/airflow/.local/lib/python3.8/site-packages/airflow/models/dag.py", line 557, in __init__
    raise ValueError("DAG is missing the start_date parameter")
ValueError: DAG is missing the start_date parameter
[2024-02-01T13:05:49.852+0000] {processor.py:842} WARNING - No viable dags retrieved from /opt/airflow/dags/s3_postgres_dag.py
[2024-02-01T13:05:49.897+0000] {processor.py:183} INFO - Processing /opt/airflow/dags/s3_postgres_dag.py took 0.084 seconds
[2024-02-01T13:06:20.308+0000] {processor.py:161} INFO - Started process (PID=74) to work on /opt/airflow/dags/s3_postgres_dag.py
[2024-02-01T13:06:20.314+0000] {processor.py:830} INFO - Processing file /opt/airflow/dags/s3_postgres_dag.py for tasks to queue
[2024-02-01T13:06:20.328+0000] {logging_mixin.py:188} INFO - [2024-02-01T13:06:20.319+0000] {dagbag.py:538} INFO - Filling up the DagBag from /opt/airflow/dags/s3_postgres_dag.py
[2024-02-01T13:06:20.415+0000] {logging_mixin.py:188} INFO - [2024-02-01T13:06:20.399+0000] {dagbag.py:348} ERROR - Failed to import: /opt/airflow/dags/s3_postgres_dag.py
Traceback (most recent call last):
  File "/home/airflow/.local/lib/python3.8/site-packages/airflow/models/dagbag.py", line 344, in parse
    loader.exec_module(new_module)
  File "<frozen importlib._bootstrap_external>", line 843, in exec_module
  File "<frozen importlib._bootstrap>", line 219, in _call_with_frames_removed
  File "/opt/airflow/dags/s3_postgres_dag.py", line 15, in <module>
    dag = DAG(
  File "/home/airflow/.local/lib/python3.8/site-packages/airflow/models/dag.py", line 557, in __init__
    raise ValueError("DAG is missing the start_date parameter")
ValueError: DAG is missing the start_date parameter
[2024-02-01T13:06:20.417+0000] {processor.py:842} WARNING - No viable dags retrieved from /opt/airflow/dags/s3_postgres_dag.py
[2024-02-01T13:06:20.516+0000] {processor.py:183} INFO - Processing /opt/airflow/dags/s3_postgres_dag.py took 0.235 seconds
[2024-02-01T13:06:50.740+0000] {processor.py:161} INFO - Started process (PID=75) to work on /opt/airflow/dags/s3_postgres_dag.py
[2024-02-01T13:06:50.741+0000] {processor.py:830} INFO - Processing file /opt/airflow/dags/s3_postgres_dag.py for tasks to queue
[2024-02-01T13:06:50.743+0000] {logging_mixin.py:188} INFO - [2024-02-01T13:06:50.742+0000] {dagbag.py:538} INFO - Filling up the DagBag from /opt/airflow/dags/s3_postgres_dag.py
[2024-02-01T13:06:50.771+0000] {logging_mixin.py:188} INFO - [2024-02-01T13:06:50.764+0000] {dagbag.py:348} ERROR - Failed to import: /opt/airflow/dags/s3_postgres_dag.py
Traceback (most recent call last):
  File "/home/airflow/.local/lib/python3.8/site-packages/airflow/models/dagbag.py", line 344, in parse
    loader.exec_module(new_module)
  File "<frozen importlib._bootstrap_external>", line 843, in exec_module
  File "<frozen importlib._bootstrap>", line 219, in _call_with_frames_removed
  File "/opt/airflow/dags/s3_postgres_dag.py", line 15, in <module>
    dag = DAG(
  File "/home/airflow/.local/lib/python3.8/site-packages/airflow/models/dag.py", line 557, in __init__
    raise ValueError("DAG is missing the start_date parameter")
ValueError: DAG is missing the start_date parameter
[2024-02-01T13:06:50.775+0000] {processor.py:842} WARNING - No viable dags retrieved from /opt/airflow/dags/s3_postgres_dag.py
[2024-02-01T13:06:50.821+0000] {processor.py:183} INFO - Processing /opt/airflow/dags/s3_postgres_dag.py took 0.084 seconds
[2024-02-01T13:07:21.204+0000] {processor.py:161} INFO - Started process (PID=76) to work on /opt/airflow/dags/s3_postgres_dag.py
[2024-02-01T13:07:21.207+0000] {processor.py:830} INFO - Processing file /opt/airflow/dags/s3_postgres_dag.py for tasks to queue
[2024-02-01T13:07:21.210+0000] {logging_mixin.py:188} INFO - [2024-02-01T13:07:21.209+0000] {dagbag.py:538} INFO - Filling up the DagBag from /opt/airflow/dags/s3_postgres_dag.py
[2024-02-01T13:07:21.266+0000] {logging_mixin.py:188} INFO - [2024-02-01T13:07:21.255+0000] {dagbag.py:348} ERROR - Failed to import: /opt/airflow/dags/s3_postgres_dag.py
Traceback (most recent call last):
  File "/home/airflow/.local/lib/python3.8/site-packages/airflow/models/dagbag.py", line 344, in parse
    loader.exec_module(new_module)
  File "<frozen importlib._bootstrap_external>", line 843, in exec_module
  File "<frozen importlib._bootstrap>", line 219, in _call_with_frames_removed
  File "/opt/airflow/dags/s3_postgres_dag.py", line 15, in <module>
    dag = DAG(
  File "/home/airflow/.local/lib/python3.8/site-packages/airflow/models/dag.py", line 557, in __init__
    raise ValueError("DAG is missing the start_date parameter")
ValueError: DAG is missing the start_date parameter
[2024-02-01T13:07:21.269+0000] {processor.py:842} WARNING - No viable dags retrieved from /opt/airflow/dags/s3_postgres_dag.py
[2024-02-01T13:07:21.330+0000] {processor.py:183} INFO - Processing /opt/airflow/dags/s3_postgres_dag.py took 0.135 seconds
[2024-02-01T13:07:45.196+0000] {processor.py:161} INFO - Started process (PID=77) to work on /opt/airflow/dags/s3_postgres_dag.py
[2024-02-01T13:07:45.197+0000] {processor.py:830} INFO - Processing file /opt/airflow/dags/s3_postgres_dag.py for tasks to queue
[2024-02-01T13:07:45.199+0000] {logging_mixin.py:188} INFO - [2024-02-01T13:07:45.199+0000] {dagbag.py:538} INFO - Filling up the DagBag from /opt/airflow/dags/s3_postgres_dag.py
[2024-02-01T13:07:45.288+0000] {logging_mixin.py:188} INFO - [2024-02-01T13:07:45.276+0000] {dagbag.py:348} ERROR - Failed to import: /opt/airflow/dags/s3_postgres_dag.py
Traceback (most recent call last):
  File "/home/airflow/.local/lib/python3.8/site-packages/airflow/models/dagbag.py", line 344, in parse
    loader.exec_module(new_module)
  File "<frozen importlib._bootstrap_external>", line 843, in exec_module
  File "<frozen importlib._bootstrap>", line 219, in _call_with_frames_removed
  File "/opt/airflow/dags/s3_postgres_dag.py", line 17, in <module>
    dag = DAG(
  File "/home/airflow/.local/lib/python3.8/site-packages/airflow/models/dag.py", line 557, in __init__
    raise ValueError("DAG is missing the start_date parameter")
ValueError: DAG is missing the start_date parameter
[2024-02-01T13:07:45.291+0000] {processor.py:842} WARNING - No viable dags retrieved from /opt/airflow/dags/s3_postgres_dag.py
[2024-02-01T13:07:45.352+0000] {processor.py:183} INFO - Processing /opt/airflow/dags/s3_postgres_dag.py took 0.161 seconds
[2024-02-01T13:08:16.270+0000] {processor.py:161} INFO - Started process (PID=78) to work on /opt/airflow/dags/s3_postgres_dag.py
[2024-02-01T13:08:16.273+0000] {processor.py:830} INFO - Processing file /opt/airflow/dags/s3_postgres_dag.py for tasks to queue
[2024-02-01T13:08:16.276+0000] {logging_mixin.py:188} INFO - [2024-02-01T13:08:16.275+0000] {dagbag.py:538} INFO - Filling up the DagBag from /opt/airflow/dags/s3_postgres_dag.py
[2024-02-01T13:08:16.306+0000] {logging_mixin.py:188} INFO - [2024-02-01T13:08:16.298+0000] {dagbag.py:348} ERROR - Failed to import: /opt/airflow/dags/s3_postgres_dag.py
Traceback (most recent call last):
  File "/home/airflow/.local/lib/python3.8/site-packages/airflow/models/dagbag.py", line 344, in parse
    loader.exec_module(new_module)
  File "<frozen importlib._bootstrap_external>", line 843, in exec_module
  File "<frozen importlib._bootstrap>", line 219, in _call_with_frames_removed
  File "/opt/airflow/dags/s3_postgres_dag.py", line 17, in <module>
    dag = DAG(
  File "/home/airflow/.local/lib/python3.8/site-packages/airflow/models/dag.py", line 557, in __init__
    raise ValueError("DAG is missing the start_date parameter")
ValueError: DAG is missing the start_date parameter
[2024-02-01T13:08:16.309+0000] {processor.py:842} WARNING - No viable dags retrieved from /opt/airflow/dags/s3_postgres_dag.py
[2024-02-01T13:08:16.380+0000] {processor.py:183} INFO - Processing /opt/airflow/dags/s3_postgres_dag.py took 0.123 seconds
[2024-02-01T13:09:05.856+0000] {processor.py:161} INFO - Started process (PID=79) to work on /opt/airflow/dags/s3_postgres_dag.py
[2024-02-01T13:09:05.888+0000] {processor.py:830} INFO - Processing file /opt/airflow/dags/s3_postgres_dag.py for tasks to queue
[2024-02-01T13:09:05.892+0000] {logging_mixin.py:188} INFO - [2024-02-01T13:09:05.891+0000] {dagbag.py:538} INFO - Filling up the DagBag from /opt/airflow/dags/s3_postgres_dag.py
[2024-02-01T13:09:06.068+0000] {logging_mixin.py:188} INFO - [2024-02-01T13:09:06.054+0000] {dagbag.py:348} ERROR - Failed to import: /opt/airflow/dags/s3_postgres_dag.py
Traceback (most recent call last):
  File "/home/airflow/.local/lib/python3.8/site-packages/airflow/models/dagbag.py", line 344, in parse
    loader.exec_module(new_module)
  File "<frozen importlib._bootstrap_external>", line 843, in exec_module
  File "<frozen importlib._bootstrap>", line 219, in _call_with_frames_removed
  File "/opt/airflow/dags/s3_postgres_dag.py", line 17, in <module>
    dag = DAG(
  File "/home/airflow/.local/lib/python3.8/site-packages/airflow/models/dag.py", line 557, in __init__
    raise ValueError("DAG is missing the start_date parameter")
ValueError: DAG is missing the start_date parameter
[2024-02-01T13:09:06.072+0000] {processor.py:842} WARNING - No viable dags retrieved from /opt/airflow/dags/s3_postgres_dag.py
[2024-02-01T13:09:07.861+0000] {processor.py:183} INFO - Processing /opt/airflow/dags/s3_postgres_dag.py took 2.011 seconds
[2024-02-01T13:09:38.160+0000] {processor.py:161} INFO - Started process (PID=80) to work on /opt/airflow/dags/s3_postgres_dag.py
[2024-02-01T13:09:38.162+0000] {processor.py:830} INFO - Processing file /opt/airflow/dags/s3_postgres_dag.py for tasks to queue
[2024-02-01T13:09:38.165+0000] {logging_mixin.py:188} INFO - [2024-02-01T13:09:38.164+0000] {dagbag.py:538} INFO - Filling up the DagBag from /opt/airflow/dags/s3_postgres_dag.py
[2024-02-01T13:09:38.201+0000] {logging_mixin.py:188} INFO - [2024-02-01T13:09:38.194+0000] {dagbag.py:348} ERROR - Failed to import: /opt/airflow/dags/s3_postgres_dag.py
Traceback (most recent call last):
  File "/home/airflow/.local/lib/python3.8/site-packages/airflow/models/dagbag.py", line 344, in parse
    loader.exec_module(new_module)
  File "<frozen importlib._bootstrap_external>", line 843, in exec_module
  File "<frozen importlib._bootstrap>", line 219, in _call_with_frames_removed
  File "/opt/airflow/dags/s3_postgres_dag.py", line 17, in <module>
    dag = DAG(
  File "/home/airflow/.local/lib/python3.8/site-packages/airflow/models/dag.py", line 557, in __init__
    raise ValueError("DAG is missing the start_date parameter")
ValueError: DAG is missing the start_date parameter
[2024-02-01T13:09:38.204+0000] {processor.py:842} WARNING - No viable dags retrieved from /opt/airflow/dags/s3_postgres_dag.py
[2024-02-01T13:09:38.253+0000] {processor.py:183} INFO - Processing /opt/airflow/dags/s3_postgres_dag.py took 0.097 seconds
[2024-02-01T13:10:09.522+0000] {processor.py:161} INFO - Started process (PID=81) to work on /opt/airflow/dags/s3_postgres_dag.py
[2024-02-01T13:10:09.523+0000] {processor.py:830} INFO - Processing file /opt/airflow/dags/s3_postgres_dag.py for tasks to queue
[2024-02-01T13:10:09.525+0000] {logging_mixin.py:188} INFO - [2024-02-01T13:10:09.524+0000] {dagbag.py:538} INFO - Filling up the DagBag from /opt/airflow/dags/s3_postgres_dag.py
[2024-02-01T13:10:09.562+0000] {logging_mixin.py:188} INFO - [2024-02-01T13:10:09.555+0000] {dagbag.py:348} ERROR - Failed to import: /opt/airflow/dags/s3_postgres_dag.py
Traceback (most recent call last):
  File "/home/airflow/.local/lib/python3.8/site-packages/airflow/models/dagbag.py", line 344, in parse
    loader.exec_module(new_module)
  File "<frozen importlib._bootstrap_external>", line 843, in exec_module
  File "<frozen importlib._bootstrap>", line 219, in _call_with_frames_removed
  File "/opt/airflow/dags/s3_postgres_dag.py", line 17, in <module>
    dag = DAG(
  File "/home/airflow/.local/lib/python3.8/site-packages/airflow/models/dag.py", line 557, in __init__
    raise ValueError("DAG is missing the start_date parameter")
ValueError: DAG is missing the start_date parameter
[2024-02-01T13:10:09.565+0000] {processor.py:842} WARNING - No viable dags retrieved from /opt/airflow/dags/s3_postgres_dag.py
[2024-02-01T13:10:09.618+0000] {processor.py:183} INFO - Processing /opt/airflow/dags/s3_postgres_dag.py took 0.100 seconds
[2024-02-01T13:10:40.496+0000] {processor.py:161} INFO - Started process (PID=82) to work on /opt/airflow/dags/s3_postgres_dag.py
[2024-02-01T13:10:40.502+0000] {processor.py:830} INFO - Processing file /opt/airflow/dags/s3_postgres_dag.py for tasks to queue
[2024-02-01T13:10:40.506+0000] {logging_mixin.py:188} INFO - [2024-02-01T13:10:40.505+0000] {dagbag.py:538} INFO - Filling up the DagBag from /opt/airflow/dags/s3_postgres_dag.py
[2024-02-01T13:10:40.607+0000] {logging_mixin.py:188} INFO - [2024-02-01T13:10:40.585+0000] {dagbag.py:348} ERROR - Failed to import: /opt/airflow/dags/s3_postgres_dag.py
Traceback (most recent call last):
  File "/home/airflow/.local/lib/python3.8/site-packages/airflow/models/dagbag.py", line 344, in parse
    loader.exec_module(new_module)
  File "<frozen importlib._bootstrap_external>", line 843, in exec_module
  File "<frozen importlib._bootstrap>", line 219, in _call_with_frames_removed
  File "/opt/airflow/dags/s3_postgres_dag.py", line 17, in <module>
    dag = DAG(
  File "/home/airflow/.local/lib/python3.8/site-packages/airflow/models/dag.py", line 557, in __init__
    raise ValueError("DAG is missing the start_date parameter")
ValueError: DAG is missing the start_date parameter
[2024-02-01T13:10:40.615+0000] {processor.py:842} WARNING - No viable dags retrieved from /opt/airflow/dags/s3_postgres_dag.py
[2024-02-01T13:10:40.659+0000] {processor.py:183} INFO - Processing /opt/airflow/dags/s3_postgres_dag.py took 0.171 seconds
[2024-02-01T13:10:54.628+0000] {processor.py:161} INFO - Started process (PID=83) to work on /opt/airflow/dags/s3_postgres_dag.py
[2024-02-01T13:10:54.629+0000] {processor.py:830} INFO - Processing file /opt/airflow/dags/s3_postgres_dag.py for tasks to queue
[2024-02-01T13:10:54.631+0000] {logging_mixin.py:188} INFO - [2024-02-01T13:10:54.630+0000] {dagbag.py:538} INFO - Filling up the DagBag from /opt/airflow/dags/s3_postgres_dag.py
[2024-02-01T13:10:54.687+0000] {logging_mixin.py:188} INFO - [2024-02-01T13:10:54.680+0000] {dagbag.py:348} ERROR - Failed to import: /opt/airflow/dags/s3_postgres_dag.py
Traceback (most recent call last):
  File "/home/airflow/.local/lib/python3.8/site-packages/airflow/models/dagbag.py", line 344, in parse
    loader.exec_module(new_module)
  File "<frozen importlib._bootstrap_external>", line 843, in exec_module
  File "<frozen importlib._bootstrap>", line 219, in _call_with_frames_removed
  File "/opt/airflow/dags/s3_postgres_dag.py", line 4, in <module>
    from airflow.operators import PythonOperator
ImportError: cannot import name 'PythonOperator' from 'airflow.operators' (/home/airflow/.local/lib/python3.8/site-packages/airflow/operators/__init__.py)
[2024-02-01T13:10:54.689+0000] {processor.py:842} WARNING - No viable dags retrieved from /opt/airflow/dags/s3_postgres_dag.py
[2024-02-01T13:10:54.728+0000] {processor.py:183} INFO - Processing /opt/airflow/dags/s3_postgres_dag.py took 0.104 seconds
[2024-02-01T13:11:25.561+0000] {processor.py:161} INFO - Started process (PID=84) to work on /opt/airflow/dags/s3_postgres_dag.py
[2024-02-01T13:11:25.562+0000] {processor.py:830} INFO - Processing file /opt/airflow/dags/s3_postgres_dag.py for tasks to queue
[2024-02-01T13:11:25.564+0000] {logging_mixin.py:188} INFO - [2024-02-01T13:11:25.563+0000] {dagbag.py:538} INFO - Filling up the DagBag from /opt/airflow/dags/s3_postgres_dag.py
[2024-02-01T13:11:25.586+0000] {logging_mixin.py:188} INFO - [2024-02-01T13:11:25.581+0000] {dagbag.py:348} ERROR - Failed to import: /opt/airflow/dags/s3_postgres_dag.py
Traceback (most recent call last):
  File "/home/airflow/.local/lib/python3.8/site-packages/airflow/models/dagbag.py", line 344, in parse
    loader.exec_module(new_module)
  File "<frozen importlib._bootstrap_external>", line 843, in exec_module
  File "<frozen importlib._bootstrap>", line 219, in _call_with_frames_removed
  File "/opt/airflow/dags/s3_postgres_dag.py", line 4, in <module>
    from airflow.operators import PythonOperator
ImportError: cannot import name 'PythonOperator' from 'airflow.operators' (/home/airflow/.local/lib/python3.8/site-packages/airflow/operators/__init__.py)
[2024-02-01T13:11:25.589+0000] {processor.py:842} WARNING - No viable dags retrieved from /opt/airflow/dags/s3_postgres_dag.py
[2024-02-01T13:11:25.660+0000] {processor.py:183} INFO - Processing /opt/airflow/dags/s3_postgres_dag.py took 0.103 seconds
[2024-02-01T13:11:55.992+0000] {processor.py:161} INFO - Started process (PID=85) to work on /opt/airflow/dags/s3_postgres_dag.py
[2024-02-01T13:11:55.993+0000] {processor.py:830} INFO - Processing file /opt/airflow/dags/s3_postgres_dag.py for tasks to queue
[2024-02-01T13:11:55.995+0000] {logging_mixin.py:188} INFO - [2024-02-01T13:11:55.994+0000] {dagbag.py:538} INFO - Filling up the DagBag from /opt/airflow/dags/s3_postgres_dag.py
[2024-02-01T13:11:56.016+0000] {logging_mixin.py:188} INFO - [2024-02-01T13:11:56.013+0000] {dagbag.py:348} ERROR - Failed to import: /opt/airflow/dags/s3_postgres_dag.py
Traceback (most recent call last):
  File "/home/airflow/.local/lib/python3.8/site-packages/airflow/models/dagbag.py", line 344, in parse
    loader.exec_module(new_module)
  File "<frozen importlib._bootstrap_external>", line 843, in exec_module
  File "<frozen importlib._bootstrap>", line 219, in _call_with_frames_removed
  File "/opt/airflow/dags/s3_postgres_dag.py", line 4, in <module>
    from airflow.operators import PythonOperator
ImportError: cannot import name 'PythonOperator' from 'airflow.operators' (/home/airflow/.local/lib/python3.8/site-packages/airflow/operators/__init__.py)
[2024-02-01T13:11:56.018+0000] {processor.py:842} WARNING - No viable dags retrieved from /opt/airflow/dags/s3_postgres_dag.py
[2024-02-01T13:11:56.065+0000] {processor.py:183} INFO - Processing /opt/airflow/dags/s3_postgres_dag.py took 0.076 seconds
[2024-02-01T13:12:26.447+0000] {processor.py:161} INFO - Started process (PID=86) to work on /opt/airflow/dags/s3_postgres_dag.py
[2024-02-01T13:12:26.448+0000] {processor.py:830} INFO - Processing file /opt/airflow/dags/s3_postgres_dag.py for tasks to queue
[2024-02-01T13:12:26.450+0000] {logging_mixin.py:188} INFO - [2024-02-01T13:12:26.449+0000] {dagbag.py:538} INFO - Filling up the DagBag from /opt/airflow/dags/s3_postgres_dag.py
[2024-02-01T13:12:26.474+0000] {logging_mixin.py:188} INFO - [2024-02-01T13:12:26.470+0000] {dagbag.py:348} ERROR - Failed to import: /opt/airflow/dags/s3_postgres_dag.py
Traceback (most recent call last):
  File "/home/airflow/.local/lib/python3.8/site-packages/airflow/models/dagbag.py", line 344, in parse
    loader.exec_module(new_module)
  File "<frozen importlib._bootstrap_external>", line 843, in exec_module
  File "<frozen importlib._bootstrap>", line 219, in _call_with_frames_removed
  File "/opt/airflow/dags/s3_postgres_dag.py", line 4, in <module>
    from airflow.operators import PythonOperator
ImportError: cannot import name 'PythonOperator' from 'airflow.operators' (/home/airflow/.local/lib/python3.8/site-packages/airflow/operators/__init__.py)
[2024-02-01T13:12:26.476+0000] {processor.py:842} WARNING - No viable dags retrieved from /opt/airflow/dags/s3_postgres_dag.py
[2024-02-01T13:12:26.516+0000] {processor.py:183} INFO - Processing /opt/airflow/dags/s3_postgres_dag.py took 0.074 seconds
[2024-02-01T13:12:56.830+0000] {processor.py:161} INFO - Started process (PID=87) to work on /opt/airflow/dags/s3_postgres_dag.py
[2024-02-01T13:12:56.832+0000] {processor.py:830} INFO - Processing file /opt/airflow/dags/s3_postgres_dag.py for tasks to queue
[2024-02-01T13:12:56.834+0000] {logging_mixin.py:188} INFO - [2024-02-01T13:12:56.833+0000] {dagbag.py:538} INFO - Filling up the DagBag from /opt/airflow/dags/s3_postgres_dag.py
[2024-02-01T13:12:56.881+0000] {logging_mixin.py:188} INFO - [2024-02-01T13:12:56.870+0000] {dagbag.py:348} ERROR - Failed to import: /opt/airflow/dags/s3_postgres_dag.py
Traceback (most recent call last):
  File "/home/airflow/.local/lib/python3.8/site-packages/airflow/models/dagbag.py", line 344, in parse
    loader.exec_module(new_module)
  File "<frozen importlib._bootstrap_external>", line 843, in exec_module
  File "<frozen importlib._bootstrap>", line 219, in _call_with_frames_removed
  File "/opt/airflow/dags/s3_postgres_dag.py", line 4, in <module>
    from airflow.operators import PythonOperator
ImportError: cannot import name 'PythonOperator' from 'airflow.operators' (/home/airflow/.local/lib/python3.8/site-packages/airflow/operators/__init__.py)
[2024-02-01T13:12:56.883+0000] {processor.py:842} WARNING - No viable dags retrieved from /opt/airflow/dags/s3_postgres_dag.py
[2024-02-01T13:12:56.928+0000] {processor.py:183} INFO - Processing /opt/airflow/dags/s3_postgres_dag.py took 0.103 seconds
[2024-02-01T13:13:27.421+0000] {processor.py:161} INFO - Started process (PID=88) to work on /opt/airflow/dags/s3_postgres_dag.py
[2024-02-01T13:13:27.423+0000] {processor.py:830} INFO - Processing file /opt/airflow/dags/s3_postgres_dag.py for tasks to queue
[2024-02-01T13:13:27.424+0000] {logging_mixin.py:188} INFO - [2024-02-01T13:13:27.423+0000] {dagbag.py:538} INFO - Filling up the DagBag from /opt/airflow/dags/s3_postgres_dag.py
[2024-02-01T13:13:27.464+0000] {logging_mixin.py:188} INFO - [2024-02-01T13:13:27.455+0000] {dagbag.py:348} ERROR - Failed to import: /opt/airflow/dags/s3_postgres_dag.py
Traceback (most recent call last):
  File "/home/airflow/.local/lib/python3.8/site-packages/airflow/models/dagbag.py", line 344, in parse
    loader.exec_module(new_module)
  File "<frozen importlib._bootstrap_external>", line 843, in exec_module
  File "<frozen importlib._bootstrap>", line 219, in _call_with_frames_removed
  File "/opt/airflow/dags/s3_postgres_dag.py", line 4, in <module>
    from airflow.operators import PythonOperator
ImportError: cannot import name 'PythonOperator' from 'airflow.operators' (/home/airflow/.local/lib/python3.8/site-packages/airflow/operators/__init__.py)
[2024-02-01T13:13:27.467+0000] {processor.py:842} WARNING - No viable dags retrieved from /opt/airflow/dags/s3_postgres_dag.py
[2024-02-01T13:13:27.523+0000] {processor.py:183} INFO - Processing /opt/airflow/dags/s3_postgres_dag.py took 0.105 seconds
[2024-02-01T13:13:58.170+0000] {processor.py:161} INFO - Started process (PID=89) to work on /opt/airflow/dags/s3_postgres_dag.py
[2024-02-01T13:13:58.173+0000] {processor.py:830} INFO - Processing file /opt/airflow/dags/s3_postgres_dag.py for tasks to queue
[2024-02-01T13:13:58.176+0000] {logging_mixin.py:188} INFO - [2024-02-01T13:13:58.175+0000] {dagbag.py:538} INFO - Filling up the DagBag from /opt/airflow/dags/s3_postgres_dag.py
[2024-02-01T13:13:58.223+0000] {logging_mixin.py:188} INFO - [2024-02-01T13:13:58.212+0000] {dagbag.py:348} ERROR - Failed to import: /opt/airflow/dags/s3_postgres_dag.py
Traceback (most recent call last):
  File "/home/airflow/.local/lib/python3.8/site-packages/airflow/models/dagbag.py", line 344, in parse
    loader.exec_module(new_module)
  File "<frozen importlib._bootstrap_external>", line 843, in exec_module
  File "<frozen importlib._bootstrap>", line 219, in _call_with_frames_removed
  File "/opt/airflow/dags/s3_postgres_dag.py", line 4, in <module>
    from airflow.operators import PythonOperator
ImportError: cannot import name 'PythonOperator' from 'airflow.operators' (/home/airflow/.local/lib/python3.8/site-packages/airflow/operators/__init__.py)
[2024-02-01T13:13:58.229+0000] {processor.py:842} WARNING - No viable dags retrieved from /opt/airflow/dags/s3_postgres_dag.py
[2024-02-01T13:13:58.322+0000] {processor.py:183} INFO - Processing /opt/airflow/dags/s3_postgres_dag.py took 0.161 seconds
[2024-02-01T13:14:28.735+0000] {processor.py:161} INFO - Started process (PID=90) to work on /opt/airflow/dags/s3_postgres_dag.py
[2024-02-01T13:14:28.737+0000] {processor.py:830} INFO - Processing file /opt/airflow/dags/s3_postgres_dag.py for tasks to queue
[2024-02-01T13:14:28.739+0000] {logging_mixin.py:188} INFO - [2024-02-01T13:14:28.738+0000] {dagbag.py:538} INFO - Filling up the DagBag from /opt/airflow/dags/s3_postgres_dag.py
[2024-02-01T13:14:28.817+0000] {logging_mixin.py:188} INFO - [2024-02-01T13:14:28.800+0000] {dagbag.py:348} ERROR - Failed to import: /opt/airflow/dags/s3_postgres_dag.py
Traceback (most recent call last):
  File "/home/airflow/.local/lib/python3.8/site-packages/airflow/models/dagbag.py", line 344, in parse
    loader.exec_module(new_module)
  File "<frozen importlib._bootstrap_external>", line 843, in exec_module
  File "<frozen importlib._bootstrap>", line 219, in _call_with_frames_removed
  File "/opt/airflow/dags/s3_postgres_dag.py", line 4, in <module>
    from airflow.operators import PythonOperator
ImportError: cannot import name 'PythonOperator' from 'airflow.operators' (/home/airflow/.local/lib/python3.8/site-packages/airflow/operators/__init__.py)
[2024-02-01T13:14:28.821+0000] {processor.py:842} WARNING - No viable dags retrieved from /opt/airflow/dags/s3_postgres_dag.py
[2024-02-01T13:14:28.929+0000] {processor.py:183} INFO - Processing /opt/airflow/dags/s3_postgres_dag.py took 0.197 seconds
[2024-02-01T13:14:59.188+0000] {processor.py:161} INFO - Started process (PID=91) to work on /opt/airflow/dags/s3_postgres_dag.py
[2024-02-01T13:14:59.190+0000] {processor.py:830} INFO - Processing file /opt/airflow/dags/s3_postgres_dag.py for tasks to queue
[2024-02-01T13:14:59.193+0000] {logging_mixin.py:188} INFO - [2024-02-01T13:14:59.192+0000] {dagbag.py:538} INFO - Filling up the DagBag from /opt/airflow/dags/s3_postgres_dag.py
[2024-02-01T13:14:59.227+0000] {logging_mixin.py:188} INFO - [2024-02-01T13:14:59.220+0000] {dagbag.py:348} ERROR - Failed to import: /opt/airflow/dags/s3_postgres_dag.py
Traceback (most recent call last):
  File "/home/airflow/.local/lib/python3.8/site-packages/airflow/models/dagbag.py", line 344, in parse
    loader.exec_module(new_module)
  File "<frozen importlib._bootstrap_external>", line 843, in exec_module
  File "<frozen importlib._bootstrap>", line 219, in _call_with_frames_removed
  File "/opt/airflow/dags/s3_postgres_dag.py", line 4, in <module>
    from airflow.operators import PythonOperator
ImportError: cannot import name 'PythonOperator' from 'airflow.operators' (/home/airflow/.local/lib/python3.8/site-packages/airflow/operators/__init__.py)
[2024-02-01T13:14:59.229+0000] {processor.py:842} WARNING - No viable dags retrieved from /opt/airflow/dags/s3_postgres_dag.py
[2024-02-01T13:14:59.268+0000] {processor.py:183} INFO - Processing /opt/airflow/dags/s3_postgres_dag.py took 0.084 seconds
[2024-02-01T13:15:29.857+0000] {processor.py:161} INFO - Started process (PID=92) to work on /opt/airflow/dags/s3_postgres_dag.py
[2024-02-01T13:15:29.859+0000] {processor.py:830} INFO - Processing file /opt/airflow/dags/s3_postgres_dag.py for tasks to queue
[2024-02-01T13:15:29.861+0000] {logging_mixin.py:188} INFO - [2024-02-01T13:15:29.860+0000] {dagbag.py:538} INFO - Filling up the DagBag from /opt/airflow/dags/s3_postgres_dag.py
[2024-02-01T13:15:29.885+0000] {logging_mixin.py:188} INFO - [2024-02-01T13:15:29.880+0000] {dagbag.py:348} ERROR - Failed to import: /opt/airflow/dags/s3_postgres_dag.py
Traceback (most recent call last):
  File "/home/airflow/.local/lib/python3.8/site-packages/airflow/models/dagbag.py", line 344, in parse
    loader.exec_module(new_module)
  File "<frozen importlib._bootstrap_external>", line 843, in exec_module
  File "<frozen importlib._bootstrap>", line 219, in _call_with_frames_removed
  File "/opt/airflow/dags/s3_postgres_dag.py", line 4, in <module>
    from airflow.operators import PythonOperator
ImportError: cannot import name 'PythonOperator' from 'airflow.operators' (/home/airflow/.local/lib/python3.8/site-packages/airflow/operators/__init__.py)
[2024-02-01T13:15:29.887+0000] {processor.py:842} WARNING - No viable dags retrieved from /opt/airflow/dags/s3_postgres_dag.py
[2024-02-01T13:15:29.933+0000] {processor.py:183} INFO - Processing /opt/airflow/dags/s3_postgres_dag.py took 0.079 seconds
[2024-02-01T13:16:00.330+0000] {processor.py:161} INFO - Started process (PID=93) to work on /opt/airflow/dags/s3_postgres_dag.py
[2024-02-01T13:16:00.331+0000] {processor.py:830} INFO - Processing file /opt/airflow/dags/s3_postgres_dag.py for tasks to queue
[2024-02-01T13:16:00.333+0000] {logging_mixin.py:188} INFO - [2024-02-01T13:16:00.332+0000] {dagbag.py:538} INFO - Filling up the DagBag from /opt/airflow/dags/s3_postgres_dag.py
[2024-02-01T13:16:00.362+0000] {logging_mixin.py:188} INFO - [2024-02-01T13:16:00.351+0000] {dagbag.py:348} ERROR - Failed to import: /opt/airflow/dags/s3_postgres_dag.py
Traceback (most recent call last):
  File "/home/airflow/.local/lib/python3.8/site-packages/airflow/models/dagbag.py", line 344, in parse
    loader.exec_module(new_module)
  File "<frozen importlib._bootstrap_external>", line 843, in exec_module
  File "<frozen importlib._bootstrap>", line 219, in _call_with_frames_removed
  File "/opt/airflow/dags/s3_postgres_dag.py", line 4, in <module>
    from airflow.operators import PythonOperator
ImportError: cannot import name 'PythonOperator' from 'airflow.operators' (/home/airflow/.local/lib/python3.8/site-packages/airflow/operators/__init__.py)
[2024-02-01T13:16:00.367+0000] {processor.py:842} WARNING - No viable dags retrieved from /opt/airflow/dags/s3_postgres_dag.py
[2024-02-01T13:16:00.497+0000] {processor.py:183} INFO - Processing /opt/airflow/dags/s3_postgres_dag.py took 0.170 seconds
[2024-02-01T13:16:30.729+0000] {processor.py:161} INFO - Started process (PID=94) to work on /opt/airflow/dags/s3_postgres_dag.py
[2024-02-01T13:16:30.730+0000] {processor.py:830} INFO - Processing file /opt/airflow/dags/s3_postgres_dag.py for tasks to queue
[2024-02-01T13:16:30.731+0000] {logging_mixin.py:188} INFO - [2024-02-01T13:16:30.731+0000] {dagbag.py:538} INFO - Filling up the DagBag from /opt/airflow/dags/s3_postgres_dag.py
[2024-02-01T13:16:30.755+0000] {logging_mixin.py:188} INFO - [2024-02-01T13:16:30.751+0000] {dagbag.py:348} ERROR - Failed to import: /opt/airflow/dags/s3_postgres_dag.py
Traceback (most recent call last):
  File "/home/airflow/.local/lib/python3.8/site-packages/airflow/models/dagbag.py", line 344, in parse
    loader.exec_module(new_module)
  File "<frozen importlib._bootstrap_external>", line 843, in exec_module
  File "<frozen importlib._bootstrap>", line 219, in _call_with_frames_removed
  File "/opt/airflow/dags/s3_postgres_dag.py", line 4, in <module>
    from airflow.operators import PythonOperator
ImportError: cannot import name 'PythonOperator' from 'airflow.operators' (/home/airflow/.local/lib/python3.8/site-packages/airflow/operators/__init__.py)
[2024-02-01T13:16:30.757+0000] {processor.py:842} WARNING - No viable dags retrieved from /opt/airflow/dags/s3_postgres_dag.py
[2024-02-01T13:16:30.804+0000] {processor.py:183} INFO - Processing /opt/airflow/dags/s3_postgres_dag.py took 0.079 seconds
[2024-02-01T13:17:01.329+0000] {processor.py:161} INFO - Started process (PID=95) to work on /opt/airflow/dags/s3_postgres_dag.py
[2024-02-01T13:17:01.332+0000] {processor.py:830} INFO - Processing file /opt/airflow/dags/s3_postgres_dag.py for tasks to queue
[2024-02-01T13:17:01.335+0000] {logging_mixin.py:188} INFO - [2024-02-01T13:17:01.334+0000] {dagbag.py:538} INFO - Filling up the DagBag from /opt/airflow/dags/s3_postgres_dag.py
[2024-02-01T13:17:01.379+0000] {logging_mixin.py:188} INFO - [2024-02-01T13:17:01.371+0000] {dagbag.py:348} ERROR - Failed to import: /opt/airflow/dags/s3_postgres_dag.py
Traceback (most recent call last):
  File "/home/airflow/.local/lib/python3.8/site-packages/airflow/models/dagbag.py", line 344, in parse
    loader.exec_module(new_module)
  File "<frozen importlib._bootstrap_external>", line 843, in exec_module
  File "<frozen importlib._bootstrap>", line 219, in _call_with_frames_removed
  File "/opt/airflow/dags/s3_postgres_dag.py", line 4, in <module>
    from airflow.operators import PythonOperator
ImportError: cannot import name 'PythonOperator' from 'airflow.operators' (/home/airflow/.local/lib/python3.8/site-packages/airflow/operators/__init__.py)
[2024-02-01T13:17:01.382+0000] {processor.py:842} WARNING - No viable dags retrieved from /opt/airflow/dags/s3_postgres_dag.py
[2024-02-01T13:17:01.433+0000] {processor.py:183} INFO - Processing /opt/airflow/dags/s3_postgres_dag.py took 0.110 seconds
[2024-02-01T13:17:31.772+0000] {processor.py:161} INFO - Started process (PID=96) to work on /opt/airflow/dags/s3_postgres_dag.py
[2024-02-01T13:17:31.773+0000] {processor.py:830} INFO - Processing file /opt/airflow/dags/s3_postgres_dag.py for tasks to queue
[2024-02-01T13:17:31.775+0000] {logging_mixin.py:188} INFO - [2024-02-01T13:17:31.775+0000] {dagbag.py:538} INFO - Filling up the DagBag from /opt/airflow/dags/s3_postgres_dag.py
[2024-02-01T13:17:31.794+0000] {logging_mixin.py:188} INFO - [2024-02-01T13:17:31.789+0000] {dagbag.py:348} ERROR - Failed to import: /opt/airflow/dags/s3_postgres_dag.py
Traceback (most recent call last):
  File "/home/airflow/.local/lib/python3.8/site-packages/airflow/models/dagbag.py", line 344, in parse
    loader.exec_module(new_module)
  File "<frozen importlib._bootstrap_external>", line 843, in exec_module
  File "<frozen importlib._bootstrap>", line 219, in _call_with_frames_removed
  File "/opt/airflow/dags/s3_postgres_dag.py", line 4, in <module>
    from airflow.operators import PythonOperator
ImportError: cannot import name 'PythonOperator' from 'airflow.operators' (/home/airflow/.local/lib/python3.8/site-packages/airflow/operators/__init__.py)
[2024-02-01T13:17:31.796+0000] {processor.py:842} WARNING - No viable dags retrieved from /opt/airflow/dags/s3_postgres_dag.py
[2024-02-01T13:17:31.832+0000] {processor.py:183} INFO - Processing /opt/airflow/dags/s3_postgres_dag.py took 0.065 seconds
[2024-02-01T13:18:02.154+0000] {processor.py:161} INFO - Started process (PID=97) to work on /opt/airflow/dags/s3_postgres_dag.py
[2024-02-01T13:18:02.155+0000] {processor.py:830} INFO - Processing file /opt/airflow/dags/s3_postgres_dag.py for tasks to queue
[2024-02-01T13:18:02.157+0000] {logging_mixin.py:188} INFO - [2024-02-01T13:18:02.156+0000] {dagbag.py:538} INFO - Filling up the DagBag from /opt/airflow/dags/s3_postgres_dag.py
[2024-02-01T13:18:02.179+0000] {logging_mixin.py:188} INFO - [2024-02-01T13:18:02.175+0000] {dagbag.py:348} ERROR - Failed to import: /opt/airflow/dags/s3_postgres_dag.py
Traceback (most recent call last):
  File "/home/airflow/.local/lib/python3.8/site-packages/airflow/models/dagbag.py", line 344, in parse
    loader.exec_module(new_module)
  File "<frozen importlib._bootstrap_external>", line 843, in exec_module
  File "<frozen importlib._bootstrap>", line 219, in _call_with_frames_removed
  File "/opt/airflow/dags/s3_postgres_dag.py", line 4, in <module>
    from airflow.operators import PythonOperator
ImportError: cannot import name 'PythonOperator' from 'airflow.operators' (/home/airflow/.local/lib/python3.8/site-packages/airflow/operators/__init__.py)
[2024-02-01T13:18:02.181+0000] {processor.py:842} WARNING - No viable dags retrieved from /opt/airflow/dags/s3_postgres_dag.py
[2024-02-01T13:18:02.229+0000] {processor.py:183} INFO - Processing /opt/airflow/dags/s3_postgres_dag.py took 0.079 seconds
[2024-02-01T13:18:19.254+0000] {processor.py:161} INFO - Started process (PID=98) to work on /opt/airflow/dags/s3_postgres_dag.py
[2024-02-01T13:18:19.258+0000] {processor.py:830} INFO - Processing file /opt/airflow/dags/s3_postgres_dag.py for tasks to queue
[2024-02-01T13:18:19.260+0000] {logging_mixin.py:188} INFO - [2024-02-01T13:18:19.260+0000] {dagbag.py:538} INFO - Filling up the DagBag from /opt/airflow/dags/s3_postgres_dag.py
[2024-02-01T13:18:19.387+0000] {logging_mixin.py:188} INFO - [2024-02-01T13:18:19.359+0000] {dagbag.py:348} ERROR - Failed to import: /opt/airflow/dags/s3_postgres_dag.py
Traceback (most recent call last):
  File "/home/airflow/.local/lib/python3.8/site-packages/airflow/models/dagbag.py", line 344, in parse
    loader.exec_module(new_module)
  File "<frozen importlib._bootstrap_external>", line 843, in exec_module
  File "<frozen importlib._bootstrap>", line 219, in _call_with_frames_removed
  File "/opt/airflow/dags/s3_postgres_dag.py", line 17, in <module>
    dag = DAG(
  File "/home/airflow/.local/lib/python3.8/site-packages/airflow/models/dag.py", line 557, in __init__
    raise ValueError("DAG is missing the start_date parameter")
ValueError: DAG is missing the start_date parameter
[2024-02-01T13:18:19.395+0000] {processor.py:842} WARNING - No viable dags retrieved from /opt/airflow/dags/s3_postgres_dag.py
[2024-02-01T13:18:19.493+0000] {processor.py:183} INFO - Processing /opt/airflow/dags/s3_postgres_dag.py took 0.253 seconds
[2024-02-01T13:18:50.233+0000] {processor.py:161} INFO - Started process (PID=99) to work on /opt/airflow/dags/s3_postgres_dag.py
[2024-02-01T13:18:50.235+0000] {processor.py:830} INFO - Processing file /opt/airflow/dags/s3_postgres_dag.py for tasks to queue
[2024-02-01T13:18:50.236+0000] {logging_mixin.py:188} INFO - [2024-02-01T13:18:50.236+0000] {dagbag.py:538} INFO - Filling up the DagBag from /opt/airflow/dags/s3_postgres_dag.py
[2024-02-01T13:18:50.269+0000] {logging_mixin.py:188} INFO - [2024-02-01T13:18:50.263+0000] {dagbag.py:348} ERROR - Failed to import: /opt/airflow/dags/s3_postgres_dag.py
Traceback (most recent call last):
  File "/home/airflow/.local/lib/python3.8/site-packages/airflow/models/dagbag.py", line 344, in parse
    loader.exec_module(new_module)
  File "<frozen importlib._bootstrap_external>", line 843, in exec_module
  File "<frozen importlib._bootstrap>", line 219, in _call_with_frames_removed
  File "/opt/airflow/dags/s3_postgres_dag.py", line 17, in <module>
    dag = DAG(
  File "/home/airflow/.local/lib/python3.8/site-packages/airflow/models/dag.py", line 557, in __init__
    raise ValueError("DAG is missing the start_date parameter")
ValueError: DAG is missing the start_date parameter
[2024-02-01T13:18:50.271+0000] {processor.py:842} WARNING - No viable dags retrieved from /opt/airflow/dags/s3_postgres_dag.py
[2024-02-01T13:18:50.338+0000] {processor.py:183} INFO - Processing /opt/airflow/dags/s3_postgres_dag.py took 0.108 seconds
[2024-02-01T13:19:21.039+0000] {processor.py:161} INFO - Started process (PID=100) to work on /opt/airflow/dags/s3_postgres_dag.py
[2024-02-01T13:19:21.041+0000] {processor.py:830} INFO - Processing file /opt/airflow/dags/s3_postgres_dag.py for tasks to queue
[2024-02-01T13:19:21.042+0000] {logging_mixin.py:188} INFO - [2024-02-01T13:19:21.042+0000] {dagbag.py:538} INFO - Filling up the DagBag from /opt/airflow/dags/s3_postgres_dag.py
[2024-02-01T13:19:21.073+0000] {logging_mixin.py:188} INFO - [2024-02-01T13:19:21.066+0000] {dagbag.py:348} ERROR - Failed to import: /opt/airflow/dags/s3_postgres_dag.py
Traceback (most recent call last):
  File "/home/airflow/.local/lib/python3.8/site-packages/airflow/models/dagbag.py", line 344, in parse
    loader.exec_module(new_module)
  File "<frozen importlib._bootstrap_external>", line 843, in exec_module
  File "<frozen importlib._bootstrap>", line 219, in _call_with_frames_removed
  File "/opt/airflow/dags/s3_postgres_dag.py", line 17, in <module>
    dag = DAG(
  File "/home/airflow/.local/lib/python3.8/site-packages/airflow/models/dag.py", line 557, in __init__
    raise ValueError("DAG is missing the start_date parameter")
ValueError: DAG is missing the start_date parameter
[2024-02-01T13:19:21.075+0000] {processor.py:842} WARNING - No viable dags retrieved from /opt/airflow/dags/s3_postgres_dag.py
[2024-02-01T13:19:21.116+0000] {processor.py:183} INFO - Processing /opt/airflow/dags/s3_postgres_dag.py took 0.080 seconds
[2024-02-01T13:19:51.586+0000] {processor.py:161} INFO - Started process (PID=101) to work on /opt/airflow/dags/s3_postgres_dag.py
[2024-02-01T13:19:51.587+0000] {processor.py:830} INFO - Processing file /opt/airflow/dags/s3_postgres_dag.py for tasks to queue
[2024-02-01T13:19:51.589+0000] {logging_mixin.py:188} INFO - [2024-02-01T13:19:51.588+0000] {dagbag.py:538} INFO - Filling up the DagBag from /opt/airflow/dags/s3_postgres_dag.py
[2024-02-01T13:19:51.618+0000] {logging_mixin.py:188} INFO - [2024-02-01T13:19:51.611+0000] {dagbag.py:348} ERROR - Failed to import: /opt/airflow/dags/s3_postgres_dag.py
Traceback (most recent call last):
  File "/home/airflow/.local/lib/python3.8/site-packages/airflow/models/dagbag.py", line 344, in parse
    loader.exec_module(new_module)
  File "<frozen importlib._bootstrap_external>", line 843, in exec_module
  File "<frozen importlib._bootstrap>", line 219, in _call_with_frames_removed
  File "/opt/airflow/dags/s3_postgres_dag.py", line 17, in <module>
    dag = DAG(
  File "/home/airflow/.local/lib/python3.8/site-packages/airflow/models/dag.py", line 557, in __init__
    raise ValueError("DAG is missing the start_date parameter")
ValueError: DAG is missing the start_date parameter
[2024-02-01T13:19:51.620+0000] {processor.py:842} WARNING - No viable dags retrieved from /opt/airflow/dags/s3_postgres_dag.py
[2024-02-01T13:19:51.661+0000] {processor.py:183} INFO - Processing /opt/airflow/dags/s3_postgres_dag.py took 0.078 seconds
[2024-02-01T13:20:22.192+0000] {processor.py:161} INFO - Started process (PID=102) to work on /opt/airflow/dags/s3_postgres_dag.py
[2024-02-01T13:20:22.194+0000] {processor.py:830} INFO - Processing file /opt/airflow/dags/s3_postgres_dag.py for tasks to queue
[2024-02-01T13:20:22.196+0000] {logging_mixin.py:188} INFO - [2024-02-01T13:20:22.195+0000] {dagbag.py:538} INFO - Filling up the DagBag from /opt/airflow/dags/s3_postgres_dag.py
[2024-02-01T13:20:22.226+0000] {logging_mixin.py:188} INFO - [2024-02-01T13:20:22.218+0000] {dagbag.py:348} ERROR - Failed to import: /opt/airflow/dags/s3_postgres_dag.py
Traceback (most recent call last):
  File "/home/airflow/.local/lib/python3.8/site-packages/airflow/models/dagbag.py", line 344, in parse
    loader.exec_module(new_module)
  File "<frozen importlib._bootstrap_external>", line 843, in exec_module
  File "<frozen importlib._bootstrap>", line 219, in _call_with_frames_removed
  File "/opt/airflow/dags/s3_postgres_dag.py", line 17, in <module>
    dag = DAG(
  File "/home/airflow/.local/lib/python3.8/site-packages/airflow/models/dag.py", line 557, in __init__
    raise ValueError("DAG is missing the start_date parameter")
ValueError: DAG is missing the start_date parameter
[2024-02-01T13:20:22.230+0000] {processor.py:842} WARNING - No viable dags retrieved from /opt/airflow/dags/s3_postgres_dag.py
[2024-02-01T13:20:22.275+0000] {processor.py:183} INFO - Processing /opt/airflow/dags/s3_postgres_dag.py took 0.087 seconds
[2024-02-01T13:20:53.450+0000] {processor.py:161} INFO - Started process (PID=103) to work on /opt/airflow/dags/s3_postgres_dag.py
[2024-02-01T13:20:53.452+0000] {processor.py:830} INFO - Processing file /opt/airflow/dags/s3_postgres_dag.py for tasks to queue
[2024-02-01T13:20:53.454+0000] {logging_mixin.py:188} INFO - [2024-02-01T13:20:53.453+0000] {dagbag.py:538} INFO - Filling up the DagBag from /opt/airflow/dags/s3_postgres_dag.py
[2024-02-01T13:20:53.485+0000] {logging_mixin.py:188} INFO - [2024-02-01T13:20:53.478+0000] {dagbag.py:348} ERROR - Failed to import: /opt/airflow/dags/s3_postgres_dag.py
Traceback (most recent call last):
  File "/home/airflow/.local/lib/python3.8/site-packages/airflow/models/dagbag.py", line 344, in parse
    loader.exec_module(new_module)
  File "<frozen importlib._bootstrap_external>", line 843, in exec_module
  File "<frozen importlib._bootstrap>", line 219, in _call_with_frames_removed
  File "/opt/airflow/dags/s3_postgres_dag.py", line 17, in <module>
    dag = DAG(
  File "/home/airflow/.local/lib/python3.8/site-packages/airflow/models/dag.py", line 557, in __init__
    raise ValueError("DAG is missing the start_date parameter")
ValueError: DAG is missing the start_date parameter
[2024-02-01T13:20:53.487+0000] {processor.py:842} WARNING - No viable dags retrieved from /opt/airflow/dags/s3_postgres_dag.py
[2024-02-01T13:20:53.530+0000] {processor.py:183} INFO - Processing /opt/airflow/dags/s3_postgres_dag.py took 0.084 seconds
